#VRML_SIM R2023b utf8
# Describe the functionality of your PROTO here.


PROTO four_omniwheels [
  field SFVec3f translation 0 0 2.5
  field SFRotation rotation 0 0 1 0
  field SFBool supervisor FALSE
  field SFString controller "omni_robot_test"
]
{
DEF OMNI_WHEELS_4 Robot {
  translation IS translation
  rotation IS rotation
  children [
    InertialUnit {
      name "IMU"
    }
    DEF SOLID1 Solid {
      rotation 0 0 1 0.7854003061004253
      children [
        DEF WHEEL1 HingeJoint {
          jointParameters HingeJointParameters {
            position -1.8058441887504393e-10
            anchor -0.1 0 0
          }
          device [
            RotationalMotor {
              name "wheel3"
              maxVelocity 40
            }
            PositionSensor {
              name "pw3"
            }
          ]
          endPoint Solid {
            translation -0.18799999999756029 5.098434940833167e-10 1.2929180695859164e-05
            rotation 0.07606655062054742 0.9971027421286328 -3.8939094387582325e-05 1.3847661203729124e-06
            children [
              DEF sr1 HingeJoint {
                jointParameters HingeJointParameters {
                  position -126.31891124653298
                  axis 0 1 0
                  anchor -0.02 0 0.05
                }
                endPoint Solid {
                  translation -0.02 0 0.05
                  rotation 0 -1 0 0.6552051029412475
                  children [
                    DEF r1 Pose {
                      rotation -1 0 0 1.5708
                      children [
                        DEF SMALL_WHEEL_SHAPE Shape {
                          appearance PBRAppearance {
                            baseColor 1 0.752941 0.796078
                            roughness 1
                            metalness 0
                          }
                          geometry Cylinder {
                            height 0.02
                            radius 0.01
                          }
                        }
                      ]
                    }
                  ]
                  name "sr1"
                  boundingObject USE r1
                  physics Physics {
                    density -1
                    mass 0.1
                  }
                }
              }
              DEF sr2 HingeJoint {
                jointParameters HingeJointParameters {
                  position 145.23932166375795
                  axis 0 -0.707107 0.707107
                  anchor -0.02 0.03535 0.03535
                }
                endPoint Solid {
                  translation -0.02 0.03535 0.03535
                  rotation 0 0.7071067811865476 -0.7071067811865476 5.557125708552127
                  children [
                    DEF r2 Pose {
                      rotation -1 0 0 2.27
                      children [
                        USE SMALL_WHEEL_SHAPE
                      ]
                    }
                  ]
                  name "sr2"
                  boundingObject USE r2
                  physics Physics {
                    density -1
                    mass 0.1
                  }
                }
              }
              DEF sr3 HingeJoint {
                jointParameters HingeJointParameters {
                  position 315.6244833338322
                  axis 0 1 0
                  anchor -0.02 0 -0.05
                }
                endPoint Solid {
                  translation -0.02 0 -0.05
                  rotation 0 1 0 1.4652179748528644
                  children [
                    DEF r3 Pose {
                      rotation -1 0 0 1.5708
                      children [
                        USE SMALL_WHEEL_SHAPE
                      ]
                    }
                  ]
                  name "sr3"
                  boundingObject USE r3
                  physics Physics {
                    density -1
                    mass 0.1
                  }
                }
              }
              DEF sr4 HingeJoint {
                jointParameters HingeJointParameters {
                  position -195.38392108712313
                  axis 0 -0.707107 0.707107
                  anchor -0.02 -0.03535 -0.03535
                }
                endPoint Solid {
                  translation -0.02 -0.03535 -0.03535
                  rotation 0 -0.7071067811865476 0.7071067811865476 5.67800874262364
                  children [
                    DEF r4 Pose {
                      rotation -1 0 0 2.27
                      children [
                        USE SMALL_WHEEL_SHAPE
                      ]
                    }
                  ]
                  name "sr4"
                  boundingObject USE r4
                  physics Physics {
                    density -1
                    mass 0.1
                  }
                }
              }
              DEF sr5 HingeJoint {
                jointParameters HingeJointParameters {
                  position 147.55102901301012
                  axis 0 0 1
                  anchor -0.02 0.05 0
                }
                endPoint Solid {
                  translation -0.02 0.05 0
                  rotation 0 0 -1 3.245418359299953
                  children [
                    DEF r5 Pose {
                      children [
                        USE SMALL_WHEEL_SHAPE
                      ]
                    }
                  ]
                  name "sr5"
                  boundingObject USE r5
                  physics Physics {
                    density -1
                    mass 0.1
                  }
                }
              }
              DEF sr6 HingeJoint {
                jointParameters HingeJointParameters {
                  position -154.2668776340013
                  axis 0 0 1
                  anchor -0.02 -0.05 0
                }
                endPoint Solid {
                  translation -0.02 -0.05 0
                  rotation 0 0 -1 3.4704302616912286
                  children [
                    DEF r6 Pose {
                      children [
                        USE SMALL_WHEEL_SHAPE
                      ]
                    }
                  ]
                  name "sr6"
                  boundingObject USE r6
                  physics Physics {
                    density -1
                    mass 0.1
                  }
                }
              }
              DEF sr7 HingeJoint {
                jointParameters HingeJointParameters {
                  position 179.5610923208043
                  axis 0 0.707107 0.707107
                  anchor -0.02 0.03535 -0.03535
                }
                endPoint Solid {
                  translation -0.02 0.03535 -0.03535
                  rotation 0 0.7071067811865476 0.7071067811865476 3.631903719775885
                  children [
                    DEF r7 Pose {
                      rotation -1 0 0 0.76
                      children [
                        USE SMALL_WHEEL_SHAPE
                      ]
                    }
                  ]
                  name "sr7"
                  boundingObject USE r7
                  physics Physics {
                    density -1
                    mass 0.1
                  }
                }
              }
              DEF sr8 HingeJoint {
                jointParameters HingeJointParameters {
                  position -151.50991554855537
                  axis 0 0.707107 0.707107
                  anchor -0.02 -0.03535 0.03535
                }
                endPoint Solid {
                  translation -0.02 -0.03535 0.03535
                  rotation 0 -0.7071067811865476 -0.7071067811865476 0.7134681762452941
                  children [
                    DEF r8 Pose {
                      rotation -1 0 0 0.76
                      children [
                        USE SMALL_WHEEL_SHAPE
                      ]
                    }
                  ]
                  name "sr8"
                  boundingObject USE r8
                  physics Physics {
                    density -1
                    mass 0.1
                  }
                }
              }
              DEF WHEEL_TRANS Pose {
                translation -0.02 0 0
                rotation 0 -1 0 1.5708
                children [
                  DEF WHEEL_SHAPE Shape {
                    appearance PBRAppearance {
                      baseColor 0.678431 0.847059 0.901961
                      roughness 1
                      metalness 0
                    }
                    geometry Cylinder {
                      height 0.02
                      radius 0.05
                      subdivision 20
                    }
                  }
                ]
              }
            ]
            boundingObject Pose {
              translation -0.02 0 0
              rotation 0 -1 0 1.5708
              children [
                DEF wheel1 Shape {
                  appearance PBRAppearance {
                    baseColor 0.8 0.8 0.8
                    transparency 0.12999999523162842
                    roughness 1
                    metalness 0
                    emissiveColor 0 1 0
                  }
                  geometry Cylinder {
                    height 0.02
                    radius 0.05
                  }
                }
              ]
            }
            physics Physics {
            }
          }
        }
      ]
      name "wheel 1"
      boundingObject DEF DUMMY Sphere {
        radius 0.01
      }
      physics Physics {
      }
    }
    DEF SOLID2 Solid {
      rotation 0 0 1 2.3561996938995744
      children [
        DEF WHEEL2 HingeJoint {
          jointParameters HingeJointParameters {
            position 1.3282820413439712e-06
            anchor -0.1 0 0
          }
          device [
            RotationalMotor {
              name "wheel4"
              maxVelocity 40
            }
            PositionSensor {
              name "pw4"
            }
          ]
          endPoint Solid {
            translation -0.1880000000430867 -5.941673163600414e-10 1.2889234711351105e-05
            rotation -0.9999998355622093 0.000573476277988195 7.161788723803991e-07 0.002404521614872332
            children [
              DEF sr1 HingeJoint {
                jointParameters HingeJointParameters {
                  position 281.32831258393514
                  axis 0 1 0
                  anchor -0.02 0 0.05
                }
                endPoint Solid {
                  translation -0.02 0 0.05
                  rotation 0 1 0 4.868159068033339
                  children [
                    USE r1
                  ]
                  name "sr1"
                  boundingObject USE r1
                  physics Physics {
                    density -1
                    mass 0.1
                  }
                }
              }
              DEF sr2 HingeJoint {
                jointParameters HingeJointParameters {
                  position -654.5466461268
                  axis 0 -0.707107 0.707107
                  anchor -0.02 0.03535 0.03535
                }
                endPoint Solid {
                  translation -0.02 0.03535 0.03535
                  rotation 0 0.7071067811865475 -0.7071067811865475 1.0953741801230623
                  children [
                    USE r2
                  ]
                  name "sr2"
                  boundingObject USE r2
                  physics Physics {
                    density -1
                    mass 0.1
                  }
                }
              }
              DEF sr3 HingeJoint {
                jointParameters HingeJointParameters {
                  position -301.8413067568631
                  axis 0 1 0
                  anchor -0.02 0 -0.05
                }
                endPoint Solid {
                  translation -0.02 0 -0.05
                  rotation 0 -1 0 0.24841201224295442
                  children [
                    USE r3
                  ]
                  name "sr3"
                  boundingObject USE r3
                  physics Physics {
                    density -1
                    mass 0.1
                  }
                }
              }
              DEF sr4 HingeJoint {
                jointParameters HingeJointParameters {
                  position 498.1894738431226
                  axis 0 -0.707107 0.707107
                  anchor -0.02 -0.03535 -0.03535
                }
                endPoint Solid {
                  translation -0.02 -0.03535 -0.03535
                  rotation 0 0.7071067811865475 -0.7071067811865475 4.4653507312443335
                  children [
                    USE r4
                  ]
                  name "sr4"
                  boundingObject USE r4
                  physics Physics {
                    density -1
                    mass 0.1
                  }
                }
              }
              DEF sr5 HingeJoint {
                jointParameters HingeJointParameters {
                  position -315.68345521681624
                  axis 0 0 1
                  anchor -0.02 0.05 0
                }
                endPoint Solid {
                  translation -0.02 0.05 0
                  rotation 0 0 -1 1.5241898578369182
                  children [
                    USE r5
                  ]
                  name "sr5"
                  boundingObject USE r5
                  physics Physics {
                    density -1
                    mass 0.1
                  }
                }
              }
              DEF sr6 HingeJoint {
                jointParameters HingeJointParameters {
                  position 573.4599676906284
                  axis 0 0 1
                  anchor -0.02 -0.05 0
                }
                endPoint Solid {
                  translation -0.02 -0.05 0
                  rotation 0 0 -1 4.59308056989351
                  children [
                    USE r6
                  ]
                  name "sr6"
                  boundingObject USE r6
                  physics Physics {
                    density -1
                    mass 0.1
                  }
                }
              }
              DEF sr7 HingeJoint {
                jointParameters HingeJointParameters {
                  position -638.5446574111318
                  axis 0 0.707107 0.707107
                  anchor -0.02 0.03535 -0.03535
                }
                endPoint Solid {
                  translation -0.02 0.03535 -0.03535
                  rotation 0 0.7071067811865475 0.7071067811865475 2.3402439211860546
                  children [
                    USE r7
                  ]
                  name "sr7"
                  boundingObject USE r7
                  physics Physics {
                    density -1
                    mass 0.1
                  }
                }
              }
              DEF sr8 HingeJoint {
                jointParameters HingeJointParameters {
                  position 452.9247071196548
                  axis 0 0.707107 0.707107
                  anchor -0.02 -0.03535 0.03535
                }
                endPoint Solid {
                  translation -0.02 -0.03535 0.03535
                  rotation 0 0.7071067811865476 0.7071067811865476 0.5353650027245574
                  children [
                    USE r8
                  ]
                  name "sr8"
                  boundingObject USE r8
                  physics Physics {
                    density -1
                    mass 0.1
                  }
                }
              }
              USE WHEEL_TRANS
            ]
            boundingObject Pose {
              translation -0.02 0 0
              rotation 0 -1 0 1.5708
              children [
                DEF wheel1 Shape {
                  appearance PBRAppearance {
                    baseColor 0.8 0.8 0.8
                    transparency 0.12999999523162842
                    roughness 1
                    metalness 0
                    emissiveColor 0 1 0
                  }
                  geometry Cylinder {
                    height 0.02
                    radius 0.05
                  }
                }
              ]
            }
            physics Physics {
            }
          }
        }
      ]
      name "wheel 2"
      boundingObject USE DUMMY
      physics Physics {
      }
    }
    DEF SOLID3 Solid {
      rotation 0 0 1 -2.3561950010791604
      children [
        DEF WHEEL3 HingeJoint {
          jointParameters HingeJointParameters {
            position -1.327236758416037e-06
            anchor -0.1 0 0
          }
          device [
            PositionSensor {
              name "pw1"
            }
            RotationalMotor {
              name "wheel1"
              maxVelocity 40
            }
          ]
          endPoint Solid {
            translation -0.18799999998986372 6.3238504040858e-10 1.290876108993885e-05
            rotation -0.9999999376060538 0.00035325265104142886 6.733617973995659e-07 0.003909440909909824
            children [
              DEF sr1 HingeJoint {
                jointParameters HingeJointParameters {
                  position 210.87284800418138
                  axis 0 1 0
                  anchor -0.02 0 0.05
                }
                endPoint Solid {
                  translation -0.02 0 0.05
                  rotation 0 -1 0 2.755452439924562
                  children [
                    USE r1
                  ]
                  name "sr1"
                  boundingObject USE r1
                  physics Physics {
                    density -1
                    mass 0.1
                  }
                }
              }
              DEF sr2 HingeJoint {
                jointParameters HingeJointParameters {
                  position -524.1689156003263
                  axis 0 -0.707107 0.707107
                  anchor -0.02 0.03535 0.03535
                }
                endPoint Solid {
                  translation -0.02 0.03535 0.03535
                  rotation 0 -0.7071067811865476 0.7071067811865476 3.6186502027589915
                  children [
                    USE r2
                  ]
                  name "sr2"
                  boundingObject USE r2
                  physics Physics {
                    density -1
                    mass 0.1
                  }
                }
              }
              DEF sr3 HingeJoint {
                jointParameters HingeJointParameters {
                  position -294.0344532679062
                  axis 0 1 0
                  anchor -0.02 0 -0.05
                }
                endPoint Solid {
                  translation -0.02 0 -0.05
                  rotation 0 -1 0 5.007929137645223
                  children [
                    USE r3
                  ]
                  name "sr3"
                  boundingObject USE r3
                  physics Physics {
                    density -1
                    mass 0.1
                  }
                }
              }
              DEF sr4 HingeJoint {
                jointParameters HingeJointParameters {
                  position 745.1432141694047
                  axis 0 -0.707107 0.707107
                  anchor -0.02 -0.03535 -0.03535
                }
                endPoint Solid {
                  translation -0.02 -0.03535 -0.03535
                  rotation 0 -0.7071067811865476 0.7071067811865476 3.727347922213496
                  children [
                    USE r4
                  ]
                  name "sr4"
                  boundingObject USE r4
                  physics Physics {
                    density -1
                    mass 0.1
                  }
                }
              }
              DEF sr5 HingeJoint {
                jointParameters HingeJointParameters {
                  position -164.32123066067865
                  axis 0 0 1
                  anchor -0.02 0.05 0
                }
                endPoint Solid {
                  translation -0.02 0.05 0
                  rotation 0 0 -1 0.958412674009403
                  children [
                    USE r5
                  ]
                  name "sr5"
                  boundingObject USE r5
                  physics Physics {
                    density -1
                    mass 0.1
                  }
                }
              }
              DEF sr6 HingeJoint {
                jointParameters HingeJointParameters {
                  position 273.9872662698736
                  axis 0 0 1
                  anchor -0.02 -0.05 0
                }
                endPoint Solid {
                  translation -0.02 -0.05 0
                  rotation 0 0 -1 2.472887246028204
                  children [
                    USE r6
                  ]
                  name "sr6"
                  boundingObject USE r6
                  physics Physics {
                    density -1
                    mass 0.1
                  }
                }
              }
              DEF sr7 HingeJoint {
                jointParameters HingeJointParameters {
                  position -337.7714670436428
                  axis 0 0.707107 0.707107
                  anchor -0.02 0.03535 -0.03535
                }
                endPoint Solid {
                  translation -0.02 0.03535 -0.03535
                  rotation 0 0.7071067811865476 0.7071067811865476 1.5205395440548546
                  children [
                    USE r7
                  ]
                  name "sr7"
                  boundingObject USE r7
                  physics Physics {
                    density -1
                    mass 0.1
                  }
                }
              }
              DEF sr8 HingeJoint {
                jointParameters HingeJointParameters {
                  position 337.1906439595693
                  axis 0 0.707107 0.707107
                  anchor -0.02 -0.03535 0.03535
                }
                endPoint Solid {
                  translation -0.02 -0.03535 0.03535
                  rotation 0 -0.7071067811865475 -0.7071067811865475 2.101362628128384
                  children [
                    USE r8
                  ]
                  name "sr8"
                  boundingObject USE r8
                  physics Physics {
                    density -1
                    mass 0.1
                  }
                }
              }
              USE WHEEL_TRANS
            ]
            boundingObject Pose {
              translation -0.02 0 0
              rotation 0 -1 0 1.5708
              children [
                DEF wheel1 Shape {
                  appearance PBRAppearance {
                    baseColor 0.8 0.8 0.8
                    transparency 0.12999999523162842
                    roughness 1
                    metalness 0
                    emissiveColor 0 1 0
                  }
                  geometry Cylinder {
                    height 0.02
                    radius 0.05
                  }
                }
              ]
            }
            physics Physics {
            }
          }
        }
      ]
      name "wheel 3"
      boundingObject USE DUMMY
      physics Physics {
      }
    }
    DEF SOLID4 Solid {
      rotation 0 0 1 -0.7854003061004253
      children [
        DEF WHEEL4 HingeJoint {
          jointParameters HingeJointParameters {
            position 2.8476879169886336e-10
            anchor -0.1 0 0
          }
          device [
            PositionSensor {
              name "pw2"
            }
            RotationalMotor {
              name "wheel2"
              maxVelocity 40
            }
          ]
          endPoint Solid {
            translation -0.1879999999437038 -5.503631232228552e-10 1.294199901567035e-05
            rotation -0.9999999372413078 0.0003542836150205137 7.074940374660913e-07 0.003908089286793902
            children [
              DEF sr1 HingeJoint {
                jointParameters HingeJointParameters {
                  position -118.8536178135532
                  axis 0 1 0
                  anchor -0.02 0 0.05
                }
                endPoint Solid {
                  translation -0.02 0 0.05
                  rotation 0 -1 0 5.756282284320643
                  children [
                    USE r1
                  ]
                  name "sr1"
                  boundingObject USE r1
                  physics Physics {
                    density -1
                    mass 0.1
                  }
                }
              }
              DEF sr2 HingeJoint {
                jointParameters HingeJointParameters {
                  position -173.12626693489975
                  axis 0 -0.707107 0.707107
                  anchor -0.02 0.03535 0.03535
                }
                endPoint Solid {
                  translation -0.02 0.03535 0.03535
                  rotation 0 -0.7071067811865475 0.7071067811865475 2.802921666128675
                  children [
                    USE r2
                  ]
                  name "sr2"
                  boundingObject USE r2
                  physics Physics {
                    density -1
                    mass 0.1
                  }
                }
              }
              DEF sr3 HingeJoint {
                jointParameters HingeJointParameters {
                  position 106.13970052100873
                  axis 0 1 0
                  anchor -0.02 0 -0.05
                }
                endPoint Solid {
                  translation -0.02 0 -0.05
                  rotation 0 1 0 5.608735606135351
                  children [
                    USE r3
                  ]
                  name "sr3"
                  boundingObject USE r3
                  physics Physics {
                    density -1
                    mass 0.1
                  }
                }
              }
              DEF sr4 HingeJoint {
                jointParameters HingeJointParameters {
                  position 342.2475934179364
                  axis 0 -0.707107 0.707107
                  anchor -0.02 -0.03535 -0.03535
                }
                endPoint Solid {
                  translation -0.02 -0.03535 -0.03535
                  rotation 0 -0.7071067811865475 0.7071067811865475 2.9555868302387305
                  children [
                    USE r4
                  ]
                  name "sr4"
                  boundingObject USE r4
                  physics Physics {
                    density -1
                    mass 0.1
                  }
                }
              }
              DEF sr5 HingeJoint {
                jointParameters HingeJointParameters {
                  position 148.49656521624223
                  axis 0 0 1
                  anchor -0.02 0.05 0
                }
                endPoint Solid {
                  translation -0.02 0.05 0
                  rotation 0 0 -0.9999999999999999 2.2998821560678437
                  children [
                    USE r5
                  ]
                  name "sr5"
                  boundingObject USE r5
                  physics Physics {
                    density -1
                    mass 0.1
                  }
                }
              }
              DEF sr6 HingeJoint {
                jointParameters HingeJointParameters {
                  position -136.86575133947642
                  axis 0 0 1
                  anchor -0.02 -0.05 0
                }
                endPoint Solid {
                  translation -0.02 -0.05 0
                  rotation 0 0 1 1.3643254184744844
                  children [
                    USE r6
                  ]
                  name "sr6"
                  boundingObject USE r6
                  physics Physics {
                    density -1
                    mass 0.1
                  }
                }
              }
              DEF sr7 HingeJoint {
                jointParameters HingeJointParameters {
                  position 12.54382658284056
                  axis 0 0.707107 0.707107
                  anchor -0.02 0.03535 -0.03535
                }
                endPoint Solid {
                  translation -0.02 0.03535 -0.03535
                  rotation 0 -0.7071067811865476 -0.7071067811865476 0.022544031518615337
                  children [
                    USE r7
                  ]
                  name "sr7"
                  boundingObject USE r7
                  physics Physics {
                    density -1
                    mass 0.1
                  }
                }
              }
              DEF sr8 HingeJoint {
                jointParameters HingeJointParameters {
                  position -30.28982012817961
                  axis 0 0.707107 0.707107
                  anchor -0.02 -0.03535 0.03535
                }
                endPoint Solid {
                  translation -0.02 -0.03535 0.03535
                  rotation 0 -0.7071067811865475 -0.7071067811865475 5.157078899461264
                  children [
                    USE r8
                  ]
                  name "sr8"
                  boundingObject USE r8
                  physics Physics {
                    density -1
                    mass 0.1
                  }
                }
              }
              USE WHEEL_TRANS
            ]
            boundingObject Pose {
              translation -0.02 0 0
              rotation 0 -1 0 1.5708
              children [
                DEF wheel1 Shape {
                  appearance PBRAppearance {
                    baseColor 0.8 0.8 0.8
                    transparency 0.12999999523162842
                    roughness 1
                    metalness 0
                    emissiveColor 0 1 0
                  }
                  geometry Cylinder {
                    height 0.02
                    radius 0.05
                  }
                }
              ]
            }
            physics Physics {
            }
          }
        }
      ]
      name "wheel 4"
      boundingObject USE DUMMY
      physics Physics {
      }
    }
    Camera {
      translation 0 0 0.4
      rotation 0 1 0 1.5708
      fieldOfView 3.14
      width 640
      height 640
      projection "spherical"
    }
    DEF BODY_TRANS Pose {
      translation 0 0 0.04
      children [
        Shape {
          appearance PBRAppearance {
            baseColor 0.564706 0.933333 0.564706
            roughness 1
            metalness 0
          }
          geometry Box {
            size 0.25 0.25 0.1
          }
        }
      ]
    }
  ]
  name "robot(1)"
  boundingObject USE BODY_TRANS
  physics Physics {
  }
  controller IS controller
  supervisor IS supervisor
}

}
